<?xml version="1.0" encoding="utf-8"?>
<!-- This URDF was automatically created by SolidWorks to URDF Exporter! Originally created by Stephen Brawner (brawner@gmail.com) 
     Commit Version: 1.6.0-4-g7f85cfe  Build Version: 1.6.7995.38578
     For more information, please see http://wiki.ros.org/sw_urdf_exporter -->
<robot
  name="URDF">
  <link
    name="base_link">
    <inertial>
      <origin
        xyz="0.226401216207925 0.0832142996809845 -0.250000000000001"
        rpy="0 0 0" />
      <mass
        value="3.00064129669064" />
      <inertia
        ixx="0.00796442280563064"
        ixy="1.36070703287508E-19"
        ixz="-3.62530101424841E-19"
        iyy="0.0128600718019731"
        iyz="-1.58651595988054E-18"
        izz="0.00543817220574471" />
    </inertial>
    <visual>
      <origin
        xyz="0 0 0"
        rpy="0 0 0" />
      <geometry>
        <mesh
          filename="package://URDF/meshes/base_link.STL" />
      </geometry>
      <material
        name="">
        <color
          rgba="0.898039215686275 0.917647058823529 0.929411764705882 1" />
      </material>
    </visual>
    <collision>
      <origin
        xyz="0 0 0"
        rpy="0 0 0" />
      <geometry>
        <mesh
          filename="package://URDF/meshes/base_link.STL" />
      </geometry>
    </collision>
  </link>
  <link
    name="steerFR">
    <inertial>
      <origin
        xyz="-5.55111512312578E-17 0 -0.0192277182691706"
        rpy="0 0 0" />
      <mass
        value="0.221804775243313" />
      <inertia
        ixx="0.000211251147171327"
        ixy="1.44292030990691E-19"
        ixz="8.59309424235824E-21"
        iyy="0.000195922267849405"
        iyz="-3.11143914323226E-21"
        izz="0.000272151766439536" />
    </inertial>
    <visual>
      <origin
        xyz="0 0 0"
        rpy="0 0 0" />
      <geometry>
        <mesh
          filename="package://URDF/meshes/steerFR.STL" />
      </geometry>
      <material
        name="">
        <color
          rgba="1 1 1 1" />
      </material>
    </visual>
    <collision>
      <origin
        xyz="0 0 0"
        rpy="0 0 0" />
      <geometry>
        <mesh
          filename="package://URDF/meshes/steerFR.STL" />
      </geometry>
    </collision>
  </link>
  <joint
    name="steerFR"
    type="fixed">
    <origin
      xyz="0.427999999999999 0.0720000000000044 0.098"
      rpy="0 0 3.14159265358979" />
    <parent
      link="base_link" />
    <child
      link="steerFR" />
    <axis
      xyz="0 0 0" />
  </joint>
  <link
    name="wheelFR">
    <inertial>
      <origin
        xyz="5.55111512312578E-17 -3.33066907387547E-16 -2.77555756156289E-17"
        rpy="0 0 0" />
      <mass
        value="0.764764182848667" />
      <inertia
        ixx="0.000394618318349911"
        ixy="-2.71050543121414E-20"
        ixz="-2.70957328763451E-18"
        iyy="0.000394618318349911"
        iyz="-8.26225347607718E-20"
        izz="0.000674522009272522" />
    </inertial>
    <visual>
      <origin
        xyz="0 0 0"
        rpy="0 0 0" />
      <geometry>
        <mesh
          filename="package://URDF/meshes/wheelFR.STL" />
      </geometry>
      <material
        name="">
        <color
          rgba="0.686274509803922 0.658823529411765 0.63921568627451 1" />
      </material>
    </visual>
    <collision>
      <origin
        xyz="0 0 0"
        rpy="0 0 0" />
      <geometry>
        <mesh
          filename="package://URDF/meshes/wheelFR.STL" />
      </geometry>
    </collision>
  </link>
  <joint
    name="wheelFR"
    type="continuous">
    <origin
      xyz="0 0 -0.056"
      rpy="-1.57079632679489 -0.316982240676282 3.14159265358979" />
    <parent
      link="steerFR" />
    <child
      link="wheelFR" />
    <axis
      xyz="0 0 1" />
  </joint>
  <link
    name="steerFL">
    <inertial>
      <origin
        xyz="5.55111512312578E-17 1.11022302462516E-16 -0.0192277182691706"
        rpy="0 0 0" />
      <mass
        value="0.221804775243313" />
      <inertia
        ixx="0.000211251147171327"
        ixy="1.47797168419444E-19"
        ixz="-1.55384921848748E-20"
        iyy="0.000195922267849405"
        iyz="-8.59475294497338E-20"
        izz="0.000272151766439536" />
    </inertial>
    <visual>
      <origin
        xyz="0 0 0"
        rpy="0 0 0" />
      <geometry>
        <mesh
          filename="package://URDF/meshes/steerFL.STL" />
      </geometry>
      <material
        name="">
        <color
          rgba="1 1 1 1" />
      </material>
    </visual>
    <collision>
      <origin
        xyz="0 0 0"
        rpy="0 0 0" />
      <geometry>
        <mesh
          filename="package://URDF/meshes/steerFL.STL" />
      </geometry>
    </collision>
  </link>
  <joint
    name="steerFL"
    type="fixed">
    <origin
      xyz="0.427999999999993 0.428000000000008 0.098"
      rpy="0 0 3.14159265358979" />
    <parent
      link="base_link" />
    <child
      link="steerFL" />
    <axis
      xyz="0 0 0" />
  </joint>
  <link
    name="wheelFL">
    <inertial>
      <origin
        xyz="-5.20417042793042E-16 -1.11022302462516E-16 -5.55111512312578E-17"
        rpy="0 0 0" />
      <mass
        value="0.764764182848668" />
      <inertia
        ixx="0.000394618318349911"
        ixy="1.35525271560716E-20"
        ixz="-5.05597455100933E-19"
        iyy="0.000394618318349911"
        iyz="-3.3275654132207E-19"
        izz="0.000674522009272522" />
    </inertial>
    <visual>
      <origin
        xyz="0 0 0"
        rpy="0 0 0" />
      <geometry>
        <mesh
          filename="package://URDF/meshes/wheelFL.STL" />
      </geometry>
      <material
        name="">
        <color
          rgba="0.686274509803922 0.658823529411765 0.63921568627451 1" />
      </material>
    </visual>
    <collision>
      <origin
        xyz="0 0 0"
        rpy="0 0 0" />
      <geometry>
        <mesh
          filename="package://URDF/meshes/wheelFL.STL" />
      </geometry>
    </collision>
  </link>
  <joint
    name="wheelFL"
    type="continuous">
    <origin
      xyz="0 0 -0.056"
      rpy="-1.57079632679491 1.37893541128008 3.14159265358979" />
    <parent
      link="steerFL" />
    <child
      link="wheelFL" />
    <axis
      xyz="0 0 1" />
  </joint>
  <link
    name="steerBL">
    <inertial>
      <origin
        xyz="0 0 -0.0192277182691706"
        rpy="0 0 0" />
      <mass
        value="0.221804775243313" />
      <inertia
        ixx="0.000211251147171327"
        ixy="1.53485357990453E-19"
        ixz="-5.82835284482216E-21"
        iyy="0.000195922267849405"
        iyz="-8.27166169107774E-20"
        izz="0.000272151766439536" />
    </inertial>
    <visual>
      <origin
        xyz="0 0 0"
        rpy="0 0 0" />
      <geometry>
        <mesh
          filename="package://URDF/meshes/steerBL.STL" />
      </geometry>
      <material
        name="">
        <color
          rgba="1 1 1 1" />
      </material>
    </visual>
    <collision>
      <origin
        xyz="0 0 0"
        rpy="0 0 0" />
      <geometry>
        <mesh
          filename="package://URDF/meshes/steerBL.STL" />
      </geometry>
    </collision>
  </link>
  <joint
    name="steerBL"
    type="fixed">
    <origin
      xyz="0.0719999999999909 0.428000000000001 0.098"
      rpy="0 0 0" />
    <parent
      link="base_link" />
    <child
      link="steerBL" />
    <axis
      xyz="0 0 0" />
  </joint>
  <link
    name="wheelBL">
    <inertial>
      <origin
        xyz="9.71445146547012E-17 3.91353616180368E-15 4.9960036108132E-16"
        rpy="0 0 0" />
      <mass
        value="0.764764182848667" />
      <inertia
        ixx="0.00039461831834991"
        ixy="8.470329472543E-22"
        ixz="9.64554885113479E-20"
        iyy="0.00039461831834991"
        iyz="2.87673481551354E-18"
        izz="0.000674522009272521" />
    </inertial>
    <visual>
      <origin
        xyz="0 0 0"
        rpy="0 0 0" />
      <geometry>
        <mesh
          filename="package://URDF/meshes/wheelBL.STL" />
      </geometry>
      <material
        name="">
        <color
          rgba="0.686274509803922 0.658823529411765 0.63921568627451 1" />
      </material>
    </visual>
    <collision>
      <origin
        xyz="0 0 0"
        rpy="0 0 0" />
      <geometry>
        <mesh
          filename="package://URDF/meshes/wheelBL.STL" />
      </geometry>
    </collision>
  </link>
  <joint
    name="wheelBL"
    type="continuous">
    <origin
      xyz="0 0 -0.056"
      rpy="1.5707963267949 1.5497746785967 0" />
    <parent
      link="steerBL" />
    <child
      link="wheelBL" />
    <axis
      xyz="0 0 1" />
  </joint>
  <link
    name="steerBR">
    <inertial>
      <origin
        xyz="1.38777878078145E-17 0 -0.0192277182691705"
        rpy="0 0 0" />
      <mass
        value="0.221804775243313" />
      <inertia
        ixx="0.000211251147171327"
        ixy="1.67216368223617E-19"
        ixz="-2.19014072580611E-20"
        iyy="0.000195922267849405"
        iyz="-1.56535916965506E-20"
        izz="0.000272151766439536" />
    </inertial>
    <visual>
      <origin
        xyz="0 0 0"
        rpy="0 0 0" />
      <geometry>
        <mesh
          filename="package://URDF/meshes/steerBR.STL" />
      </geometry>
      <material
        name="">
        <color
          rgba="1 1 1 1" />
      </material>
    </visual>
    <collision>
      <origin
        xyz="0 0 0"
        rpy="0 0 0" />
      <geometry>
        <mesh
          filename="package://URDF/meshes/steerBR.STL" />
      </geometry>
    </collision>
  </link>
  <joint
    name="steerBR"
    type="fixed">
    <origin
      xyz="0.071999999999999 0.0720000000000007 0.098"
      rpy="0 0 0" />
    <parent
      link="base_link" />
    <child
      link="steerBR" />
    <axis
      xyz="0 0 0" />
  </joint>
  <link
    name="wheelBR">
    <inertial>
      <origin
        xyz="6.10622663543836E-16 3.60822483003176E-16 -1.38777878078145E-17"
        rpy="0 0 0" />
      <mass
        value="0.764764182848667" />
      <inertia
        ixx="0.000394618318349911"
        ixy="9.48676900924816E-20"
        ixz="-2.38221637064903E-18"
        iyy="0.000394618318349911"
        iyz="-1.50429089505785E-18"
        izz="0.000674522009272522" />
    </inertial>
    <visual>
      <origin
        xyz="0 0 0"
        rpy="0 0 0" />
      <geometry>
        <mesh
          filename="package://URDF/meshes/wheelBR.STL" />
      </geometry>
      <material
        name="">
        <color
          rgba="0.686274509803922 0.658823529411765 0.63921568627451 1" />
      </material>
    </visual>
    <collision>
      <origin
        xyz="0 0 0"
        rpy="0 0 0" />
      <geometry>
        <mesh
          filename="package://URDF/meshes/wheelBR.STL" />
      </geometry>
    </collision>
  </link>
  <joint
    name="wheelBR"
    type="continuous">
    <origin
      xyz="0 0 -0.056"
      rpy="-1.5707963267949 -0.57401915441884 3.14159265358979" />
    <parent
      link="steerBR" />
    <child
      link="wheelBR" />
    <axis
      xyz="0 0 1" />
  </joint>
</robot>