<?xml version="1.0" encoding="utf-8"?>
<!-- This URDF was automatically created by SolidWorks to URDF Exporter! Originally created by Stephen Brawner (brawner@gmail.com) 
     Commit Version: 1.6.0-4-g7f85cfe  Build Version: 1.6.7995.38578
     For more information, please see http://wiki.ros.org/sw_urdf_exporter -->
<robot
  name="urdf7">
  <link
    name="base_link">
    <inertial>
      <origin
        xyz="0.226401216207925 0.0832142996809814 -0.250000000000002"
        rpy="0 0 0" />
      <mass
        value="3.00064129669064" />
      <inertia
        ixx="0.00796442280563064"
        ixy="1.25138237860794E-19"
        ixz="-3.69306365002875E-19"
        iyy="0.0128600718019731"
        iyz="-1.51411853296425E-18"
        izz="0.00543817220574472" />
    </inertial>
    <visual>
      <origin
        xyz="0 0 0"
        rpy="0 0 0" />
      <geometry>
        <mesh
          filename="package://urdf7/meshes/base_link.STL" />
      </geometry>
      <material
        name="">
        <color
          rgba="0.898039215686275 0.917647058823529 0.929411764705882 1" />
      </material>
    </visual>
    <collision>
      <origin
        xyz="0 0 0"
        rpy="0 0 0" />
      <geometry>
        <mesh
          filename="package://urdf7/meshes/base_link.STL" />
      </geometry>
    </collision>
  </link>
  <link
    name="st_fr">
    <inertial>
      <origin
        xyz="1.0547118733939E-15 -6.12010442324618E-15 0.0517722817308343"
        rpy="0 0 0" />
      <mass
        value="0.221804775243313" />
      <inertia
        ixx="0.000211251147171327"
        ixy="1.5785020728078E-19"
        ixz="3.46790690716169E-21"
        iyy="0.000195922267849405"
        iyz="8.12670481776353E-21"
        izz="0.000272151766439536" />
    </inertial>
    <visual>
      <origin
        xyz="0 0 0"
        rpy="0 0 0" />
      <geometry>
        <mesh
          filename="package://urdf7/meshes/st_fr.STL" />
      </geometry>
      <material
        name="">
        <color
          rgba="1 1 1 1" />
      </material>
    </visual>
    <collision>
      <origin
        xyz="0 0 0"
        rpy="0 0 0" />
      <geometry>
        <mesh
          filename="package://urdf7/meshes/st_fr.STL" />
      </geometry>
    </collision>
  </link>
  <joint
    name="st_fr"
    type="continuous">
    <origin
      xyz="0.427999999999999 0.0720000000000044 0.0269999999999952"
      rpy="0 0 0" />
    <parent
      link="base_link" />
    <child
      link="st_fr" />
    <axis
      xyz="0 0 1" />
  </joint>
  <link
    name="wh_fr">
    <inertial>
      <origin
        xyz="-5.55111512312578E-17 2.77555756156289E-17 6.10622663543836E-15"
        rpy="0 0 0" />
      <mass
        value="0.764764182848667" />
      <inertia
        ixx="0.000394618318349911"
        ixy="-2.71050543121376E-20"
        ixz="-2.68066210887539E-18"
        iyy="0.000394618318349911"
        iyz="-9.167375055187E-19"
        izz="0.000674522009272522" />
    </inertial>
    <visual>
      <origin
        xyz="0 0 0"
        rpy="0 0 0" />
      <geometry>
        <mesh
          filename="package://urdf7/meshes/wh_fr.STL" />
      </geometry>
      <material
        name="">
        <color
          rgba="0.686274509803922 0.658823529411765 0.63921568627451 1" />
      </material>
    </visual>
    <collision>
      <origin
        xyz="0 0 0"
        rpy="0 0 0" />
      <geometry>
        <mesh
          filename="package://urdf7/meshes/wh_fr.STL" />
      </geometry>
    </collision>
  </link>
  <joint
    name="wh_fr"
    type="continuous">
    <origin
      xyz="0 0 0.0150000000000048"
      rpy="-1.5707963267949 -0.316982240676282 3.14159265358979" />
    <parent
      link="st_fr" />
    <child
      link="wh_fr" />
    <axis
      xyz="0 0 1" />
  </joint>
  <link
    name="st_fl">
    <inertial>
      <origin
        xyz="6.10622663543836E-15 -6.21724893790088E-15 0.0517722817308343"
        rpy="0 0 0" />
      <mass
        value="0.221804775243313" />
      <inertia
        ixx="0.000211251147171327"
        ixy="1.51130406754329E-19"
        ixz="8.42111717249425E-21"
        iyy="0.000195922267849405"
        iyz="-5.86063240394111E-20"
        izz="0.000272151766439536" />
    </inertial>
    <visual>
      <origin
        xyz="0 0 0"
        rpy="0 0 0" />
      <geometry>
        <mesh
          filename="package://urdf7/meshes/st_fl.STL" />
      </geometry>
      <material
        name="">
        <color
          rgba="1 1 1 1" />
      </material>
    </visual>
    <collision>
      <origin
        xyz="0 0 0"
        rpy="0 0 0" />
      <geometry>
        <mesh
          filename="package://urdf7/meshes/st_fl.STL" />
      </geometry>
    </collision>
  </link>
  <joint
    name="st_fl"
    type="continuous">
    <origin
      xyz="0.427999999999997 0.428000000000004 0.0269999999999951"
      rpy="0 0 0" />
    <parent
      link="base_link" />
    <child
      link="st_fl" />
    <axis
      xyz="0 0 1" />
  </joint>
  <link
    name="wh_fl">
    <inertial>
      <origin
        xyz="0 0 6.21724893790088E-15"
        rpy="0 0 0" />
      <mass
        value="0.764764182848668" />
      <inertia
        ixx="0.000394618318349911"
        ixy="0"
        ixz="-5.56279878249985E-19"
        iyy="0.000394618318349911"
        iyz="2.77764143153309E-18"
        izz="0.000674522009272522" />
    </inertial>
    <visual>
      <origin
        xyz="0 0 0"
        rpy="0 0 0" />
      <geometry>
        <mesh
          filename="package://urdf7/meshes/wh_fl.STL" />
      </geometry>
      <material
        name="">
        <color
          rgba="0.686274509803922 0.658823529411765 0.63921568627451 1" />
      </material>
    </visual>
    <collision>
      <origin
        xyz="0 0 0"
        rpy="0 0 0" />
      <geometry>
        <mesh
          filename="package://urdf7/meshes/wh_fl.STL" />
      </geometry>
    </collision>
  </link>
  <joint
    name="wh_fl"
    type="continuous">
    <origin
      xyz="0 0 0.0150000000000049"
      rpy="-1.5707963267949 1.37893541128007 3.14159265358979" />
    <parent
      link="st_fl" />
    <child
      link="wh_fl" />
    <axis
      xyz="0 0 1" />
  </joint>
  <link
    name="st_bl">
    <inertial>
      <origin
        xyz="-5.55111512312578E-17 5.55111512312578E-17 0.0517722817308294"
        rpy="0 0 0" />
      <mass
        value="0.221804775243313" />
      <inertia
        ixx="0.000211251147171327"
        ixy="1.54560692786772E-19"
        ixz="-6.07336053282238E-21"
        iyy="0.000195922267849405"
        iyz="-8.09299705478716E-20"
        izz="0.000272151766439536" />
    </inertial>
    <visual>
      <origin
        xyz="0 0 0"
        rpy="0 0 0" />
      <geometry>
        <mesh
          filename="package://urdf7/meshes/st_bl.STL" />
      </geometry>
      <material
        name="">
        <color
          rgba="1 1 1 1" />
      </material>
    </visual>
    <collision>
      <origin
        xyz="0 0 0"
        rpy="0 0 0" />
      <geometry>
        <mesh
          filename="package://urdf7/meshes/st_bl.STL" />
      </geometry>
    </collision>
  </link>
  <joint
    name="st_bl"
    type="continuous">
    <origin
      xyz="0.0719999999999934 0.428000000000001 0.0269999999999999"
      rpy="0 0 0" />
    <parent
      link="base_link" />
    <child
      link="st_bl" />
    <axis
      xyz="0 0 1" />
  </joint>
  <link
    name="wh_bl">
    <inertial>
      <origin
        xyz="-7.63278329429795E-17 -9.71445146547012E-17 0"
        rpy="0 0 0" />
      <mass
        value="0.764764182848668" />
      <inertia
        ixx="0.000394618318349911"
        ixy="8.470329472543E-22"
        ixz="1.04246469853974E-19"
        iyy="0.000394618318349911"
        iyz="2.87657101211516E-18"
        izz="0.000674522009272522" />
    </inertial>
    <visual>
      <origin
        xyz="0 0 0"
        rpy="0 0 0" />
      <geometry>
        <mesh
          filename="package://urdf7/meshes/wh_bl.STL" />
      </geometry>
      <material
        name="">
        <color
          rgba="0.686274509803922 0.658823529411765 0.63921568627451 1" />
      </material>
    </visual>
    <collision>
      <origin
        xyz="0 0 0"
        rpy="0 0 0" />
      <geometry>
        <mesh
          filename="package://urdf7/meshes/wh_bl.STL" />
      </geometry>
    </collision>
  </link>
  <joint
    name="wh_bl"
    type="continuous">
    <origin
      xyz="0 0 0.015"
      rpy="1.5707963267949 1.5497746785967 0" />
    <parent
      link="st_bl" />
    <child
      link="wh_bl" />
    <axis
      xyz="0 0 1" />
  </joint>
  <link
    name="st_br">
    <inertial>
      <origin
        xyz="-4.16333634234434E-17 -1.38777878078145E-17 0.0517722817308295"
        rpy="0 0 0" />
      <mass
        value="0.221804775243313" />
      <inertia
        ixx="0.000211251147171327"
        ixy="1.67216368223617E-19"
        ixz="-1.86308560167406E-20"
        iyy="0.000195922267849405"
        iyz="-1.60327974750367E-20"
        izz="0.000272151766439536" />
    </inertial>
    <visual>
      <origin
        xyz="0 0 0"
        rpy="0 0 0" />
      <geometry>
        <mesh
          filename="package://urdf7/meshes/st_br.STL" />
      </geometry>
      <material
        name="">
        <color
          rgba="1 1 1 1" />
      </material>
    </visual>
    <collision>
      <origin
        xyz="0 0 0"
        rpy="0 0 0" />
      <geometry>
        <mesh
          filename="package://urdf7/meshes/st_br.STL" />
      </geometry>
    </collision>
  </link>
  <joint
    name="st_br"
    type="continuous">
    <origin
      xyz="0.072 0.0719999999999996 0.0269999999999999"
      rpy="0 0 0" />
    <parent
      link="base_link" />
    <child
      link="st_br" />
    <axis
      xyz="0 0 1" />
  </joint>
  <link
    name="wh_br">
    <inertial>
      <origin
        xyz="6.93889390390723E-18 1.38777878078145E-17 -1.38777878078145E-17"
        rpy="0 0 0" />
      <mass
        value="0.764764182848667" />
      <inertia
        ixx="0.000394618318349911"
        ixy="4.06575814682064E-20"
        ixz="-2.37144111384372E-18"
        iyy="0.000394618318349911"
        iyz="-1.50660309843309E-18"
        izz="0.000674522009272522" />
    </inertial>
    <visual>
      <origin
        xyz="0 0 0"
        rpy="0 0 0" />
      <geometry>
        <mesh
          filename="package://urdf7/meshes/wh_br.STL" />
      </geometry>
      <material
        name="">
        <color
          rgba="0.686274509803922 0.658823529411765 0.63921568627451 1" />
      </material>
    </visual>
    <collision>
      <origin
        xyz="0 0 0"
        rpy="0 0 0" />
      <geometry>
        <mesh
          filename="package://urdf7/meshes/wh_br.STL" />
      </geometry>
    </collision>
  </link>
  <joint
    name="wh_br"
    type="continuous">
    <origin
      xyz="0 0 0.015"
      rpy="-1.5707963267949 -0.57401915441884 3.14159265358979" />
    <parent
      link="st_br" />
    <child
      link="wh_br" />
    <axis
      xyz="0 0 1" />
  </joint>
</robot>